Workbook
Name SegmentaçãodeDados_CLIENTE_TOMADOR: #N/A
Name SegmentaçãodeDados_SERVICO: #N/A

Sheet Base
A1: MINUTA | B1: BASE | C1: DATA COLETA | D1: DATA | E1: FAT | F1: CT-E | G1: CLIENTE TOMADOR | H1: VENDEDOR | I1: VALOR NF | J1: SERVICO | K1: TIPO CTE | L1: DESTINO | M1: FRETE | N1: VOLUMES | O1: PESO | P1: RESP. COLETA | Q1: CUSTO COLETA | R1: RESP. ENTREGA | S1: CUSTO ENTREGA | T1: RESP. TRANSF | U1: CUSTO TRANSF | V1: ICMS/ISS | W1: DIFAL | X1: C.DESPACHO | Y1: SEGURO | Z1: OUTROS | AA1: C.TOTAL | AB1: RECEITA | AC1: IMPOSTO | AD1: RESULTADO | AE1: COMIS | AF1: LUCRO LIQ | AG1: MARGEM | AH1: Coluna1
A2: 305009 | B2: MATRIZ | C2: 46303 | D2: 46304 | F2: 204691-1 | G2: SAMSONITE BRASI | H2: MARLON MARQUES | I2: 1812.66 | J2: EXPRESSO_200 | K2: CTE NORMAL | L2: SAO PAULO - SP | M2: 183.06 | N2: 6 | O2: 215 | P2: PEX LOGISTICA INTEGRADA L | Q2: 15.41 | R2: DENIS MACEDO DE SOUZA | S2: 1800 | T2: ENIO PEDRO VARGAS | U2: 0 | V2: 21.97 | W2: 0 | X2: 0 | Y2: 0.91 | Z2: 0 | AA2: 1087.24 | AB2: -904.18 | AC2: 47.6 | AD2: -951.78 | AE2: 0 | AF2: -951.78 | AG2: -5.1993
A3: 305243 | B3: MATRIZ | C3: 46305 | D3: 46305 | F3: 2320-6 | G3: MATTEL DO BRASI | H3: MARLON MARQUES | I3: 24558.31 | J3: EXPRESSO_250 | K3: CTE NORMAL | L3: SAO JOSE DOS PINHAIS - PR | M3: 1887.4 | N3: 96 | O3: 171.76 | P3: N/D | Q3: 0 | R3: N/D | S3: 0 | T3: ENIO PEDRO VARGAS | U3: 0 | V3: 226.49 | W3: 0 | X3: 0 | Y3: 12.28 | Z3: 0 | AA3: 1038.15 | AB3: 849.25 | AC3: 490.72 | AD3: 358.53 | AE3: 0 | AF3: 358.53 | AG3: 0.19

Sheet Análise
E1: FATURAMENTO
E2: Faturamento | H2: Peso | J2: Venda KG | M2: Veículo | P2: Peso Veículo | S2: Taxa Ocupação Veículo
E3: ='Resumo Detalhado'!B2 -> 2070.46 | H3: ='Resumo Detalhado'!C2 -> 386.76 | J3: =E3/H3 -> 5.3533457 | M3: 3/4 | P3: 3500 | S3: =MIN(H3/P3,1) -> 0.11050286
E5: CUSTO VARIÁVEL SINTÉTICO
E6: C.Variável Total | J6: Custo KG Total CV | M6: % Fat x C.V Total | P6: Custo Total | S6: Custo KG Total
E7: =E11+K11+Q11 -> 1815.41 | J7: =E7/H3 -> 4.6938929 | M7: =E7/E3 -> 0.87681481 | P7: =E11+K11+Q11+E15+K15+Q15+E19+H19+K19 -> 2573.9704 | S7: =P7/H3 -> 6.6552136
E9: CUSTO VARIÁVEL ANÁLITICO
E10: C.Transf. | H10: Custo KG Transf. | K10: C.Entrega | N10: Custo KG Entrega | Q10: C.Coleta | T10: Custo KG Coleta
D11: =IF(E11=0,K11,E11) -> 1800 | E11: =ROUNDUP('Resumo Detalhado'!F2,0) -> 0 | H11: =E11/H3 -> 0 | K11: 1800 | N11: =K11/H3 -> 4.654049 | Q11: ='Resumo Detalhado'!D2 -> 15.41 | T11: =Q11/H3 -> 0.039843831 | W11: TIPO DE VEÍCULO | Y11: CAP.PESO
W12: Carreta | Y12: 22000
E13: IMPOSTOS | W13: Truck | Y13: 11000
E14: C.Icms | K14: I.Federais + C.Fixo | W14: Toco | Y14: 6000
E15: ='Resumo Detalhado'!H2 -> 248.46 | K15: ='Resumo Detalhado'!K2+'Resumo Detalhado'!L2 -> 331.2736 | W15: 3/4 | Y15: 3500
W16: Van | Y16: 1200
E17: OUTROS CUSTOS | O17: TARGET
E18: C.Seguro | H18: C.M.O(Outros) | K18: C.Comissão | N18: TRECHO | S18: VALOR | W18: STATUS DA CONTRATAÇÃO
E19: ='Resumo Detalhado'!I2 -> 13.19 | H19: ='Resumo Detalhado'!J2 -> 0 | K19: ='Resumo Detalhado'!L2 -> 165.6368 | N19: Navegantes-Sc X São Jose dos Pinhais-Pr3/4 | S19: 1800 | W19: =IF(D11=S19,"NO TARGET",IF(D11<S19,"ABAIXO DO TARGET",IF(D11>S19,"FORA DO TARGET"))) -> NO TARGET
E21: RESULTADO
E22: Resultado Operacional | N22: Margem Bruta
E23: ='Resumo Detalhado'!N2 -> -172.2368 | N23: =E23/E3 -> -0.083187697

Sheet Resumo Detalhado
A1: SERVICO | B1: (Tudo)
B2: =SUM(B6:B5000) -> 2070.46 | C2: =SUM(C6:C5000) -> 386.76 | D2: =SUM(D6:D5000) -> 15.41 | E2: =SUM(E6:E5000) -> 1800 | F2: =SUM(F6:F5000) -> 0 | H2: =SUM(H6:H5000) -> 248.46 | I2: =SUM(I6:I5000) -> 13.19 | J2: =SUM(J6:J5000) -> 0 | K2: =SUM(K6:K5000) -> 165.6368 | L2: =SUM(L6:L5000) -> 165.6368 | M2: =SUM(M6:M5000) -> 0 | N2: =SUM(N6:N5000) -> -172.2368 | O2: =SUM(O6:O5000) -> #DIV/0! | P2: =SUM(P6:P5000) -> 0
B3: Valores
A4: CLIENTE | B4: FATURAMENTO | C4: PESO FAT. | D4: C.COLETA | E4: C.ENTREGA | F4: C.TRANSF | G4: META C.VARIÁVEL | H4: C.ICMS | I4: C.SEGURO | J4: C.OUTROS | K4: I.FEDERAIS. | L4: C.FIXO. | M4: C.COMIS | N4: Resultado Oper. | O4: MARGEM BRUTA.
A5: MATTEL DO BRASI
A6: 305243 | B6: 1887.4 | C6: 171.76 | D6: 0 | E6: 0 | F6: 0 | G6: 0 | H6: 226.49 | I6: 12.28 | J6: 0 | K6: 150.992 | L6: 150.992 | M6: 0 | N6: 1497.638 | O6: 0.79349264
A7: SAMSONITE BRASI
A8: 305009 | B8: 183.06 | C8: 215 | D8: 15.41 | E8: 1800 | F8: 0 | G8: 9.9170217 | H8: 21.97 | I8: 0.91 | J8: 0 | K8: 14.6448 | L8: 14.6448 | M8: 0 | N8: -1669.8748 | O8: -9.1220081
A9: (vazio)
A10: (vazio) | G10: #DIV/0! | K10: 0 | L10: 0 | N10: 0 | O10: #DIV/0!

Sheet Resumo Detalhado Grafico
A1: SERVICO | B1: (Tudo)
B2: =SUM(B6:B5000) -> 183.06 | C2: =SUM(C6:C5000) -> -1669.8748
B3: Valores
A4: CLIENTE | B4: Faturamento. | C4: Resultado Oper.
A5: MATTEL DO BRASI | B5: 1887.4 | C5: 1497.638
A6: SAMSONITE BRASI | B6: 183.06 | C6: -1669.8748
A7: (vazio) | C7: 0

Sheet Target
A1: TRECHO | B1: TIPO VEÍCULO | C1: CONCATENADO | D1: VALOR
A2: Ascurra-Sc X Itajai-Sc | B2: 3/4 | C2: Ascurra-Sc X Itajai-Sc3/4 | D2: 800
A3: Barueri-Sp X São Paulo-Sp | B3: truck | C3: Barueri-Sp X São Paulo-Sptruck | D3: 900
A4: Belo Horizonte-Mg X Garuva-Sc | B4: van | C4: Belo Horizonte-Mg X Garuva-Scvan | D4: 4300
A5: Belo Horizonte-Mg X Itajai-Sc | B5: fiorino | C5: Belo Horizonte-Mg X Itajai-Scfiorino | D5: 3500
A6: Biguaçu-Sc X São Paulo-Sp | B6: van | C6: Biguaçu-Sc X São Paulo-Spvan | D6: 2500
A7: Blumenau-Sc X Guarulhos-Sp | B7: carreta | C7: Blumenau-Sc X Guarulhos-Spcarreta | D7: 5500
A8: Blumenau-Sc X Guarulhos-Sp | B8: truck | C8: Blumenau-Sc X Guarulhos-Sptruck | D8: 4100
A9: Blumenau-Sc X Suzano-Sp | B9: truck | C9: Blumenau-Sc X Suzano-Sptruck | D9: 4300
A10: Camboriu-Sc X Cabo de Santo Agostinho-Pe | B10: 3/4 | C10: Camboriu-Sc X Cabo de Santo Agostinho-Pe3/4 | D10: 14800
A11: Camboriu-Sc X Cabo de Santo Agostinho-Pe | B11: truck | C11: Camboriu-Sc X Cabo de Santo Agostinho-Petruck | D11: 18000
A12: Camboriu-Sc X Cabo de Santo Agostinho-Pe | B12: carreta | C12: Camboriu-Sc X Cabo de Santo Agostinho-Pecarreta | D12: 25000
A13: Camboriu-Sc X Cajamar-Sp | B13: 3/4 | C13: Camboriu-Sc X Cajamar-Sp3/4 | D13: 3200
... A177: Pomerode-Sc X Guarulhos-Sp | B177: toco | C177: Pomerode-Sc X Guarulhos-Sptoco | D177: 4000
A178: Navegantes-Sc X Cajamar-Sp | B178: 46085 | C178: Navegantes-Sc X Cajamar-Sp3/4 | D178: 3200
A179: Pomerode-Sc X Guarulhos-Sp | B179: truck | C179: Pomerode-Sc X Guarulhos-Sptruck | D179: 4100
A180: Sao Paulo-Sp X Brasilia-Df | B180: 46085 | C180: Sao Paulo-Sp X Brasilia-Df3/4 | D180: 5800
A181: Navegantes-Sc X Guarulhos-Sp | B181: truck | C181: Navegantes-Sc X Guarulhos-Sptruck | D181: 4100
A182: Itajai-Sc X Sao Paulo-Sp | B182: truck | C182: Itajai-Sc X Sao Paulo-Sptruck | D182: 4100
A183: Sao Paulo-Sp X Contagem-Mg | B183: truck | C183: Sao Paulo-Sp X Contagem-Mgtruck | D183: 3800
A184: Itajai-Sc X Rio de Janeiro-Rj | B184: fiorino | C184: Itajai-Sc X Rio de Janeiro-Rjfiorino | D184: 3500
A185: São Paulo-Sp X São Paulo-Sp | B185: truck | C185: São Paulo-Sp X São Paulo-Sptruck | D185: 1200
A186: Vinhedo-Sp X Guarulhos-Sp | B186: carreta | C186: Vinhedo-Sp X Guarulhos-Spcarreta | D186: 2300
A187: Itajai-Sc X Caxias do Sul-Rs | B187: 46085 | C187: Itajai-Sc X Caxias do Sul-Rs3/4 | D187: 3200
A188: São Paulo-Sp X Cascavel-Pr | B188: truck | C188: São Paulo-Sp X Cascavel-Prtruck | D188: 5000
C189: Itajai-Sc X Colombo-Prvan | D189: 1500
C190: São Paulo-Sp X Itapeva-SpVan | D190: 1900
C191: Araraquara-Sp X Santos-Sp3/4 | D191: 1800
C192: Campinas-Sp X Suzano-Spcarreta | D192: 2500
C193: Garuva-Sc X Itajai-Sc3/4 | D193: 800
C194: Guarulhos-Sp X São Paulo-Sptruck | D194: 1200
C195: Itajai-Sc X Arapongas-Pr3/4 | D195: 3200
C196: Itajai-Sc X Balneario Camboriu-Scvan | D196: 580
C197: Itajai-Sc X Blumenau-Scfiorino | D197: 400
C198: Itajai-Sc X Blumenau-Sctoco | D198: 900
C199: Itajai-Sc X Blumenau-Sctruck | D199: 1200
C200: Itajai-Sc X Blumenau-Sccarreta | D200: 1500
... C372: Navegantes-Sc X Guarulhos-Sptoco | D372: 3800
A373: Itajaí-Sc X Salvador-Ba | B373: toco | C373: Itajaí-Sc X Salvador-Batoco | D373: 14200
A374: Navegantes-Sc X Contagem-Mg | B374: carreta | C374: Navegantes-Sc X Contagem-Mgcarreta | D374: 9300
...
